Workbook

Sheet Executive Summary
A1: 207 Main Street, Amagansett — Market Rent Analysis
A2: Commercial market rent assessment, effective 2026-10-07. Rent basis: annual base rent per SF, triple-net (NNN) unless labelled otherwise.
A3: Built from '207 Main Street, Amagansett — Commercial Market Rent Assessment' (research/reports). All outputs are live formulas driven by the three master inputs below.
A4: MASTER INPUTS (edit these cells; every other tab links here)
A5: Input | B5: Value | C5: Unit | D5: Provenance / source
A6: Building area | B6: 1100 | C6: SF | D6: Broker-reported, unverified: every source traces to the 2016 Douglas Elliman listing ('The one story building is 1100 sf', quoted by Patch [9]) and the former operator's memoir [18]. No government record confirms it (NYS roll has no building-area field [1]; PropertyShark 'not shown' [3]). CB 50% coverage cap on ~2,178 SF lot ≈ 1,089 SF [6].
A7: Current monthly rent | B7: 5000 | C7: $/month | D7: Client-provided. Lease type (gross vs NNN), term, escalations and whether this is the lease assigned in 2017 are Unknown.
A8: NNN load assumption | B8: 7 | C8: $/SF/yr | D8: Report-derived ESTIMATE, range $5.00–$8.75: taxes $1.38–$3.22/SF on small village buildings [68]–[71]; subject taxes ~$2.96/SF [3]; 74A taxes $4.92/SF [31]; stated all-in Amagansett NNN $8.94/SF at 2095 Montauk [42]; national benchmark $4–$8/SF [72]. Insurance/maintenance unsourced.
A10: SUBJECT PROPERTY
A11: Address | B11: 207 Main Street, Amagansett, NY 11930 (Town of East Hampton, Suffolk County); north side of Main St (NY-27), between 203 Main St and the Town parking lot at 209 Main St | F11: [2]
A12: Parcel | B12: SCTM 300-171-1-18 (print key 171.-1-18), SWIS 472489 | F12: [1][7] Grade A
A13: Owner of record | B13: Amagansett Associates, 146 Oxford Blvd, Garden City, NY 11530 (every roll year 2021–2025; also owns 203 Main St) | F13: [1][2] Grade A
A14: Property class | B14: 483 'Converted Residence' (not 421 Restaurant) | F14: [1] Grade A
A15: Building SF | B15: =TEXT($B$6,"#,##0")&" SF, one story — broker-reported (2016 Elliman listing) and memoir; unverified by any government record" -> 1,100 SF, one story — broker-reported (2016 Elliman listing) and memoir; unverified by any government record | F15: [9][18] Grade B/C
A16: Lot | B16: 0.05 acre, about 2,178 SF (could be ~1,960–2,370 SF given rounding); below the CB minimum lot area of 3,000 SF | F16: [3][11][6]
A17: Historic status | B17: Town Code ch. 255, App. A § A-5(C)(1): one of nine historic commercial buildings ('First Great Atlantic and Pacific Tea Company (The Coach Factory Store)'); alterations and signage go to the ARB | F17: [4][7] Grade A
A18: Zoning | B18: Central Business (CB), highly probable but not confirmed on a zoning map; restaurant and take-out food store permitted (P) in CB per the 2018 use table | F18: [4][5][7] Grade A
A19: Parking / patio / kitchen | B19: No on-site parking (adjoins Town lot); patio: yes; kitchen 'not much bigger than a bathroom' | F19: [2][9][18]
A20: Current operation | B20: Organic Krush (since June 2017); posted hours Fri–Mon; seasonal winter closures | F20: [19][22][24]
A21: Real estate taxes (2025-26) | B21: 3261 | F21: [3] Grade D
A22: Real estate taxes $/SF | B22: =B21/$B$6 -> 2.9645455 | F22: ESTIMATE
A24: CURRENT RENT
A25: Current monthly rent | B25: =$B$7 -> 5000 | C25: Master input
A26: Current annual rent | B26: =$B$7*12 -> 60000 | C26: Monthly × 12
A27: Current $/SF/yr | B27: =B26/$B$6 -> 54.545455 | C27: Annual ÷ SF (report: $54.55 at 1,100 SF)
A28: If gross: net-equivalent $/SF/yr | B28: =B27-$B$8 -> 47.545455 | C28: Current $/SF less NNN load (report: about $47.55)
A29: Taxes as % of current rent | B29: =B21/B26 -> 0.05435 | C29: Report: about 5.4%
A31: ESTIMATED MARKET RANGE (reconciled ESTIMATE)
A32: Measure | B32: Low | C32: Midpoint | D32: High | E32: Note
A33: $/SF/yr NNN | B33: ='Market Rent Analysis'!$B$55 -> 60 | C33: ='Market Rent Analysis'!$C$55 -> 66 | D33: ='Market Rent Analysis'!$D$55 -> 72 | E33: From Market Rent Analysis (report: $60 / $66 / $72)
A34: $/SF/yr gross-equivalent | B34: =B33+$B$8 -> 67 | C34: =C33+$B$8 -> 73 | D34: =D33+$B$8 -> 79 | E34: NNN + master NNN load
A35: Monthly rent, subject (NNN) | B35: =B33*$B$6/12 -> 5500 | C35: =C33*$B$6/12 -> 6050 | D35: =D33*$B$6/12 -> 6600 | E35: $/SF × SF ÷ 12 (report: $5,500 / $6,050 / $6,600)
A36: Annual rent, subject (NNN) | B36: =B35*12 -> 66000 | C36: =C35*12 -> 72600 | D36: =D35*12 -> 79200
A37: Monthly rent, gross-equivalent | B37: =B34*$B$6/12 -> 6141.6667 | C37: =C34*$B$6/12 -> 6691.6667 | D37: =D34*$B$6/12 -> 7241.6667
A38: Current rent vs market (NNN basis) | B38: =$B$7/B35-1 -> -0.090909091 | C38: =$B$7/C35-1 -> -0.17355372 | D38: =$B$7/D35-1 -> -0.24242424 | E38: Report: about −9% / −17% / −24%
A39: Market midpoint | B39: =C33 -> 66 | C39: =C35 -> 6050 | D39: $/SF NNN → monthly (Method B weighted $66.24, rounded)
A41: RECOMMENDED LANDLORD POSITION
A42: Position | B42: Monthly | C42: $/SF/yr (NNN) | D42: Annual | E42: % over current | F42: Basis
A43: Conservative | B43: ='Market Rent Analysis'!C74 -> 5500 | C43: =B43*12/$B$6 -> 60 | D43: =B43*12 -> 66000 | E43: =B43/$B$7-1 -> 0.1 | F43: Low end of reconciled range; lowest market-supported rent the landlord can credibly defend
A44: Fair market midpoint | B44: ='Market Rent Analysis'!C75 -> 6050 | C44: =B44*12/$B$6 -> 66 | D44: =B44*12 -> 72600 | E44: =B44/$B$7-1 -> 0.21 | F44: Method B weighted result, rounded; recommended reset target at renewal
...

Sheet Comparable Properties
A1: Comparable Properties — de-duplicated comparables table (23 rows)
A2: Annual base rent per SF; NNN unless labelled. Monthly, Rent/SF, NNN/CAM and Effective Rent/SF are formulas. Effective Rent/SF = Rent/SF + NNN (stated figure where the report has one, otherwise the master NNN assumption) + key money ÷ amortization years ÷ SF.
A3: Label for each row (ASK / CLOSED / EXECUTED / HISTORICAL ASK) is shown in brackets at the start of Notes, exactly as the report labels it. Tier 1 = Amagansett Main St/Montauk Hwy food service ~500–3,000 SF; Tier 2 = other Amagansett commercial; Tier 3 = other Hamptons hamlets. Score 1 (weak) to 5 (near-identical).
A4: Property | B4: Address | C4: City | D4: Property Type | E4: SF | F4: Lease Type | G4: Annual Base Rent | H4: Monthly Base Rent | I4: Rent/SF | J4: NNN/CAM | K4: Effective Rent/SF | L4: Lease Term | M4: Seasonality | N4: Date | O4: Source | P4: Source Quality | Q4: Comparability Score | R4: Tier | S4: Notes | T4: Source URL
A5: Former Coche Comedor (annual option) | B5: 74A Montauk Hwy | C5: Amagansett | D5: Turnkey restaurant, 126 seats | E5: 2830 | F5: NNN | G5: 240000 | H5: =IF(ISNUMBER(G5),G5/12,"n/a") -> 20000 | I5: =IFERROR(IF(ISNUMBER(G5),G5/E5,"n/a"),"n/a") -> 84.805654 | J5: =IF(SUMPRODUCT(($A$42:$A$42=A5)*$B$42:$B$42)>0,SUMPRODUCT(($A$42:$A$42=A5)*$B$42:$B$42)/E5,IF(AND(LEFT(F5,3)="NNN",ISNUMBER(I5)),"Not stated; master "&TEXT('Executive Summary'!$B$8,"$0.00")&" applied","Unknown")) -> Not stated; master $7.00 applied | K5: =IF(AND(ISNUMBER(I5),LEFT(F5,3)="NNN"),I5+IF(ISNUMBER(J5),J5,'Executive Summary'!$B$8)+SUMPRODUCT(($A$37:$A$39=A5)*$B$37:$B$39)/$C$31/E5,"n/a") -> 116.54064 | L5: Multi-year; Crexi shows 3 mo–10 yr (D) | M5: Annual | N5: Listed 2026-03-26; ~194 days, no cut | O5: [28][29][30][31][32] | P5: B | Q5: 3 | R5: 1 | S5: [ASK] Report row 1. SF = 2,830 main level + finished lower level. Plus $700,000 key money (ASK) incl. equipment; 31 on-site spaces; renovated 2020; central A/C. Taxes $13,919 = $4.92/SF (D); full NNN Unknown, so master NNN applied. Report's gross-equiv. column ($91.81) excludes key money; Effective Rent/SF here adds key money ÷ amortization years ÷ SF. | T5: https://hamptonscommercialre.com/properties/iconic-amagansett-restaurant-turn-key-opportunity/ | https://www.compass.com/homedetails/74-A-Montauk-Hwy-Amagansett-NY-11930/2070541251466245481_lid/ | https://www.hamptonsrealestate.com/eng/hampton-rentals/detail/524-l-526-930465/74a-montauk-highway-amagansett-ny-11930 | https://www.cityfeet.com/cont/listing/74a-montauk-hwy-amagansett-ny-11930/cs39907135 | https://www.crexi.com/lease/properties/1155311/new-york-74a-montauk-highway---iconic-amagansett-restaurant
A6: Same space (seasonal option) | B6: 74A Montauk Hwy | C6: Amagansett | D6: Turnkey restaurant (same space) | E6: 2830 | F6: Unknown | G6: Seasonal: $175,000 for May 22–Sep 15, 2026 (lapsed) | H6: =IF(ISNUMBER(G6),G6/12,"n/a") -> n/a | I6: =IFERROR(IF(ISNUMBER(G6),G6/E6,"n/a"),"n/a") -> n/a | J6: =IF(SUMPRODUCT(($A$42:$A$42=A6)*$B$42:$B$42)>0,SUMPRODUCT(($A$42:$A$42=A6)*$B$42:$B$42)/E6,IF(AND(LEFT(F6,3)="NNN",ISNUMBER(I6)),"Not stated; master "&TEXT('Executive Summary'!$B$8,"$0.00")&" applied","Unknown")) -> Unknown | K6: =IF(AND(ISNUMBER(I6),LEFT(F6,3)="NNN"),I6+IF(ISNUMBER(J6),J6,'Executive Summary'!$B$8)+SUMPRODUCT(($A$37:$A$39=A6)*$B$37:$B$39)/$C$31/E6,"n/a") -> n/a | L6: 2026 season only | M6: Seasonal | N6: 2026 | O6: [28][31] | P6: B (D for dates) | Q6: 3 | R6: 1 | S6: [ASK] Report row 2. $61.84/SF per season; annual-equiv. $82.45–$92.30 (÷0.75 to ÷0.67): see seasonal block below. Seasonal ask = 72.9% of annual ask, consistent with the 2/3–3/4 broker rule [91]. | T6: https://hamptonscommercialre.com/properties/iconic-amagansett-restaurant-turn-key-opportunity/ | https://www.cityfeet.com/cont/listing/74a-montauk-hwy-amagansett-ny-11930/cs39907135
A7: 11 Indian Wells Hwy, first floor | B7: 11 Indian Wells Hwy | C7: Amagansett | D7: Dry flex/retail, no kitchen | E7: 2480 | F7: NNN | G7: 161200 | H7: =IF(ISNUMBER(G7),G7/12,"n/a") -> 13433.333 | I7: =IFERROR(IF(ISNUMBER(G7),G7/E7,"n/a"),"n/a") -> 65 | J7: =IF(SUMPRODUCT(($A$42:$A$42=A7)*$B$42:$B$42)>0,SUMPRODUCT(($A$42:$A$42=A7)*$B$42:$B$42)/E7,IF(AND(LEFT(F7,3)="NNN",ISNUMBER(I7)),"Not stated; master "&TEXT('Executive Summary'!$B$8,"$0.00")&" applied","Unknown")) -> Not stated; master $7.00 applied | K7: =IF(AND(ISNUMBER(I7),LEFT(F7,3)="NNN"),I7+IF(ISNUMBER(J7),J7,'Executive Summary'!$B$8)+SUMPRODUCT(($A$37:$A$39=A7)*$B$37:$B$39)/$C$31/E7,"n/a") -> 72 | L7: Negotiable (Compass '1-12 months' appears a template field) | M7: Annual | N7: Published 2025-11-25; ~316 days | O7: [33][36][37] | P7: B | Q7: 3 | R7: 2 | S7: [ASK] Report row 3. Main St district; raised entry stair; shared 33-space lot; historic building [4]. NNN not stated; building taxes ~$1.31–$2.02/SF [36]. | T7: https://hamptonscommercialre.com/properties/first-floor-commercial-space/ | https://hamptonscommercialre.com/properties/premier-amagansett-commercial-assemblage-136-main-street-11-indian-wells-hwy-amagansett/ | https://www.crexi.com/lease/properties/718872/new-york-11-indian-wells-hwy
A8: 11 Indian Wells Hwy, ground level | B8: 11 Indian Wells Hwy | C8: Amagansett | D8: Lower-level flex | E8: 2877 | F8: NNN | G8: 100695 | H8: =IF(ISNUMBER(G8),G8/12,"n/a") -> 8391.25 | I8: =IFERROR(IF(ISNUMBER(G8),G8/E8,"n/a"),"n/a") -> 35 | J8: =IF(SUMPRODUCT(($A$42:$A$42=A8)*$B$42:$B$42)>0,SUMPRODUCT(($A$42:$A$42=A8)*$B$42:$B$42)/E8,IF(AND(LEFT(F8,3)="NNN",ISNUMBER(I8)),"Not stated; master "&TEXT('Executive Summary'!$B$8,"$0.00")&" applied","Unknown")) -> Not stated; master $7.00 applied | K8: =IF(AND(ISNUMBER(I8),LEFT(F8,3)="NNN"),I8+IF(ISNUMBER(J8),J8,'Executive Summary'!$B$8)+SUMPRODUCT(($A$37:$A$39=A8)*$B$37:$B$39)/$C$31/E8,"n/a") -> 42 | L8: Negotiable | M8: Annual | N8: Available 2025-04-08; ~547 days | O8: [34][36] | P8: B | Q8: 2 | R8: 2 | S8: [ASK] Report row 4. Rear-lot access; no storefront visibility. NNN not stated; building taxes ~$1.31–$2.02/SF [36]. | T8: https://hamptonscommercialre.com/properties/ground-level-commercial-offering/ | https://hamptonscommercialre.com/properties/premier-amagansett-commercial-assemblage-136-main-street-11-indian-wells-hwy-amagansett/
A9: 11 Indian Wells Hwy, second floor | B9: 11 Indian Wells Hwy | C9: Amagansett | D9: Upper-floor flex/office | E9: 2844 | F9: NNN | G9: 142200 | H9: =IF(ISNUMBER(G9),G9/12,"n/a") -> 11850 | I9: =IFERROR(IF(ISNUMBER(G9),G9/E9,"n/a"),"n/a") -> 50 | J9: =IF(SUMPRODUCT(($A$42:$A$42=A9)*$B$42:$B$42)>0,SUMPRODUCT(($A$42:$A$42=A9)*$B$42:$B$42)/E9,IF(AND(LEFT(F9,3)="NNN",ISNUMBER(I9)),"Not stated; master "&TEXT('Executive Summary'!$B$8,"$0.00")&" applied","Unknown")) -> Not stated; master $7.00 applied | K9: =IF(AND(ISNUMBER(I9),LEFT(F9,3)="NNN"),I9+IF(ISNUMBER(J9),J9,'Executive Summary'!$B$8)+SUMPRODUCT(($A$37:$A$39=A9)*$B$37:$B$39)/$C$31/E9,"n/a") -> 57 | L9: Negotiable | M9: Annual | N9: ~314 days on market | O9: [35] | P9: B | Q9: 1 | R9: 2 | S9: [ASK] Report row 5. Reference only. NNN not stated. | T9: https://hamptonscommercialre.com/properties/second-floor-amagansett-commercial-flex-space-iconic-building/
A10: 136 Main St, Unit 1 (end cap) | B10: 136 Main St | C10: Amagansett | D10: Dry retail end cap | E10: 500 | F10: NNN | G10: 96000 | H10: =IF(ISNUMBER(G10),G10/12,"n/a") -> 8000 | I10: =IFERROR(IF(ISNUMBER(G10),G10/E10,"n/a"),"n/a") -> 192 | J10: =IF(SUMPRODUCT(($A$42:$A$42=A10)*$B$42:$B$42)>0,SUMPRODUCT(($A$42:$A$42=A10)*$B$42:$B$42)/E10,IF(AND(LEFT(F10,3)="NNN",ISNUMBER(I10)),"Not stated; master "&TEXT('Executive Summary'!$B$8,"$0.00")&" applied","Unknown")) -> Not stated; master $7.00 applied | K10: =IF(AND(ISNUMBER(I10),LEFT(F10,3)="NNN"),I10+IF(ISNUMBER(J10),J10,'Executive Summary'!$B$8)+SUMPRODUCT(($A$37:$A$39=A10)*$B$37:$B$39)/$C$31/E10,"n/a") -> 199 | L10: Negotiable | M10: Annual | N10: 2025–26; broker page 404 on 2026-10-07, likely leased or withdrawn | O10: [38][39][40] | P10: D (terms); B (withdrawal) | Q10: 2 | R10: 2 | S10: [ASK (last ask)] Report row 6. Small-unit trophy outlier; EXCLUDED from the conclusion. | T10: https://www.loopnet.com/Listing/136-Main-St-Amagansett-NY/32986784/ | https://hamptonscommercialre.com/properties/retail-end-cap-prime-visibility/ | https://www.compass.com/agents/the-hamptons-commercial-real-estate-team/
A11: 136 Main St warehouse | B11: 136 Main St | C11: Amagansett | D11: Warehouse / flex | E11: 2000 | F11: Unstated | G11: 180000 | H11: =IF(ISNUMBER(G11),G11/12,"n/a") -> 15000 | I11: =IFERROR(IF(ISNUMBER(G11),G11/E11,"n/a"),"n/a") -> 90 | J11: =IF(SUMPRODUCT(($A$42:$A$42=A11)*$B$42:$B$42)>0,SUMPRODUCT(($A$42:$A$42=A11)*$B$42:$B$42)/E11,IF(AND(LEFT(F11,3)="NNN",ISNUMBER(I11)),"Not stated; master "&TEXT('Executive Summary'!$B$8,"$0.00")&" applied","Unknown")) -> Unknown | K11: =IF(AND(ISNUMBER(I11),LEFT(F11,3)="NNN"),I11+IF(ISNUMBER(J11),J11,'Executive Summary'!$B$8)+SUMPRODUCT(($A$37:$A$39=A11)*$B$37:$B$39)/$C$31/E11,"n/a") -> n/a | L11: Unknown | M11: Annual | N11: Available 2025-04-10; 'Permanently Off Market' | O11: [41] | P11: B | Q11: 1 | R11: 2 | S11: [HISTORICAL ASK] Report row 7. Not storefront or food. Lease type unstated, so no effective rent is computed (report: n/a). | T11: https://www.compass.com/listing/136-main-street-amagansett-ny-11930/1819738165409919177/
A12: 2095 Montauk Hwy restaurant | B12: 2095 Montauk Hwy | C12: Amagansett 11930 (Napeague, ~6 mi east of core) | D12: Restaurant, white box, 123 seats, double hood, 3BR apartment | E12: 4476 | F12: NNN | G12: 180000 | H12: =IF(ISNUMBER(G12),G12/12,"n/a") -> 15000 | I12: =IFERROR(IF(ISNUMBER(G12),G12/E12,"n/a"),"n/a") -> 40.214477 | J12: =IF(SUMPRODUCT(($A$42:$A$42=A12)*$B$42:$B$42)>0,SUMPRODUCT(($A$42:$A$42=A12)*$B$42:$B$42)/E12,IF(AND(LEFT(F12,3)="NNN",ISNUMBER(I12)),"Not stated; master "&TEXT('Executive Summary'!$B$8,"$0.00")&" applied","Unknown")) -> 8.9365505 | K12: =IF(AND(ISNUMBER(I12),LEFT(F12,3)="NNN"),I12+IF(ISNUMBER(J12),J12,'Executive Summary'!$B$8)+SUMPRODUCT(($A$37:$A$39=A12)*$B$37:$B$39)/$C$31/E12,"n/a") -> 49.151028 | L12: Unknown | M12: Annual lease; highly seasonal stretch | N12: Closed 2025-06-08 | O12: [42][40][43] | P12: B | Q12: 2 | R12: 2 | S12: [CLOSED] Report row 8. Compass 'Rented' 2025-06-08; price flagged 'Unverified'. Stated NNN $40,000/yr = $8.94/SF is used instead of the master assumption. Same $180,000 asked in fall 2024 [43]; Compass header shows '$180,000/mo', a display error against '$180,000/yr' in the listing text. | T12: https://www.compass.com/homedetails/2095-Montauk-Hwy-Amagansett-NY-11930/1826297907410452777_lid/ | https://www.compass.com/agents/the-hamptons-commercial-real-estate-team/ | https://behindthehedges.com/fall-2024-food-market-commercial-real-estate
A13: 519–521 Montauk Hwy | B13: 519–521 Montauk Hwy | C13: Amagansett (east of core) | D13: Former restaurant shell, seats 186 | E13: 5000 | F13: NNN | G13: Rate on request | H13: =IF(ISNUMBER(G13),G13/12,"n/a") -> n/a | I13: =IFERROR(IF(ISNUMBER(G13),G13/E13,"n/a"),"n/a") -> n/a | J13: =IF(SUMPRODUCT(($A$42:$A$42=A13)*$B$42:$B$42)>0,SUMPRODUCT(($A$42:$A$42=A13)*$B$42:$B$42)/E13,IF(AND(LEFT(F13,3)="NNN",ISNUMBER(I13)),"Not stated; master "&TEXT('Executive Summary'!$B$8,"$0.00")&" applied","Unknown")) -> Unknown | K13: =IF(AND(ISNUMBER(I13),LEFT(F13,3)="NNN"),I13+IF(ISNUMBER(J13),J13,'Executive Summary'!$B$8)+SUMPRODUCT(($A$37:$A$39=A13)*$B$37:$B$39)/$C$31/E13,"n/a") -> n/a | L13: Negotiable | M13: Annual | N13: Lease status unverified 2026; sale ask $7.95M (2023) | O13: [44][45][46] | P13: D (status); B (2023 facts) | Q13: 2 | R13: 2 | S13: [ASK] Report row 9. 80 parking spaces; vacant for years. Rate on request, so no $/SF. | T13: https://www.tenantbase.com/us/building/196079 | https://behindthehedges.com/amagansett-commercial-property-lists-8-million | https://www.cityfeet.com/cont/listing/519-521-montauk-hwy-amagansett-ny-11930/cs39871633
A14: 249 Main St, Building B pop-up | B14: 249 Main St | C14: Amagansett | D14: Pop-up retail; 1,000 SF ground + 1,000 SF basement + loft | E14: 2000 | F14: Unknown | G14: Seasonal: '50K' for May 1–Sept 2021 (ambiguous) | H14: =IF(ISNUMBER(G14),G14/12,"n/a") -> n/a | I14: =IFERROR(IF(ISNUMBER(G14),G14/E14,"n/a"),"n/a") -> n/a | J14: =IF(SUMPRODUCT(($A$42:$A$42=A14)*$B$42:$B$42)>0,SUMPRODUCT(($A$42:$A$42=A14)*$B$42:$B$42)/E14,IF(AND(LEFT(F14,3)="NNN",ISNUMBER(I14)),"Not stated; master "&TEXT('Executive Summary'!$B$8,"$0.00")&" applied","Unknown")) -> Unknown | K14: =IF(AND(ISNUMBER(I14),LEFT(F14,3)="NNN"),I14+IF(ISNUMBER(J14),J14,'Executive Summary'!$B$8)+SUMPRODUCT(($A$37:$A$39=A14)*$B$37:$B$39)/$C$31/E14,"n/a") -> n/a | L14: Season | M14: Seasonal | N14: 2021 | O14: [47] | P14: C | Q14: 2 | R14: 2 | S14: [HISTORICAL ASK] Report row 10. Main St and municipal-lot access; built 1786. $25–$50/SF per season; annual-equiv. $33–$75 (÷0.75 to ÷0.67, on 2,000 or 1,000 SF): see seasonal block below. | T14: https://www.corcoran.com/listing/for-rent/249-main-street-amagansett-ny-11930/5981523/regionId/3
A15: 17 S Edison St restaurant | B15: 17 S Edison St | C15: Montauk (downtown) | D15: Turnkey restaurant, ~126 seats incl. 18 sidewalk | E15: 2729 | F15: NNN | G15: 156000 | H15: =IF(ISNUMBER(G15),G15/12,"n/a") -> 13000 | I15: =IFERROR(IF(ISNUMBER(G15),G15/E15,"n/a"),"n/a") -> 57.163796 | J15: =IF(SUMPRODUCT(($A$42:$A$42=A15)*$B$42:$B$42)>0,SUMPRODUCT(($A$42:$A$42=A15)*$B$42:$B$42)/E15,IF(AND(LEFT(F15,3)="NNN",ISNUMBER(I15)),"Not stated; master "&TEXT('Executive Summary'!$B$8,"$0.00")&" applied","Unknown")) -> Not stated; master $7.00 applied | K15: =IF(AND(ISNUMBER(I15),LEFT(F15,3)="NNN"),I15+IF(ISNUMBER(J15),J15,'Executive Summary'!$B$8)+SUMPRODUCT(($A$37:$A$39=A15)*$B$37:$B$39)/$C$31/E15,"n/a") -> 73.324661 | L15: Not stated | M15: Annual | N15: Page modified 2026-08-16 | O15: [50] | P15: B | Q15: 3 | R15: 3 | S15: [ASK] Report row 11. Plus $250,000 key money (ASK); large kitchen, 112 SF walk-in freezer. Report's gross-equiv. ($64.16) excludes key money. | T15: https://hamptonscommercialre.com/properties/17-s-edison-st-montauk-restaurant/
A16: 53 The Circle (GreyVen) | B16: 53 The Circle | C16: East Hampton Village | D16: Luxury retail | E16: 1635 | F16: NNN | G16: 237075 | H16: =IF(ISNUMBER(G16),G16/12,"n/a") -> 19756.25 | I16: =IFERROR(IF(ISNUMBER(G16),G16/E16,"n/a"),"n/a") -> 145 | J16: =IF(SUMPRODUCT(($A$42:$A$42=A16)*$B$42:$B$42)>0,SUMPRODUCT(($A$42:$A$42=A16)*$B$42:$B$42)/E16,IF(AND(LEFT(F16,3)="NNN",ISNUMBER(I16)),"Not stated; master "&TEXT('Executive Summary'!$B$8,"$0.00")&" applied","Unknown")) -> Not stated; master $7.00 applied | K16: =IF(AND(ISNUMBER(I16),LEFT(F16,3)="NNN"),I16+IF(ISNUMBER(J16),J16,'Executive Summary'!$B$8)+SUMPRODUCT(($A$37:$A$39=A16)*$B$37:$B$39)/$C$31/E16,"n/a") -> 152 | L16: Unknown | M16: Annual | N16: 2024-05-09 | O16: [53] | P16: D (internally corroborated) | Q16: 1 | R16: 3 | S16: [EXECUTED] Report row 12. Executed per Traded.co, closed 2024-05-09. 6% × $3,959,000 sale ask = $237,540, matching the rent; trophy, EXCLUDED except as ceiling. | T16: https://traded.co/deals/new-york/retail/lease/53-the-circle-1/
A17: 53 The Circle (current ask) | B17: 53 The Circle | C17: East Hampton Village | D17: Luxury retail + storage basement | E17: 1600 | F17: NNN | G17: 240000 | H17: =IF(ISNUMBER(G17),G17/12,"n/a") -> 20000 | I17: =IFERROR(IF(ISNUMBER(G17),G17/E17,"n/a"),"n/a") -> 150 | J17: =IF(SUMPRODUCT(($A$42:$A$42=A17)*$B$42:$B$42)>0,SUMPRODUCT(($A$42:$A$42=A17)*$B$42:$B$42)/E17,IF(AND(LEFT(F17,3)="NNN",ISNUMBER(I17)),"Not stated; master "&TEXT('Executive Summary'!$B$8,"$0.00")&" applied","Unknown")) -> Not stated; master $7.00 applied | K17: =IF(AND(ISNUMBER(I17),LEFT(F17,3)="NNN"),I17+IF(ISNUMBER(J17),J17,'Executive Summary'!$B$8)+SUMPRODUCT(($A$37:$A$39=A17)*$B$37:$B$39)/$C$31/E17,"n/a") -> 157 | L17: Unknown | M17: Annual | N17: Modified 2026-01-13; April 2026 sale page cites 'The tenancy' | O17: [51][52] | P17: B | Q17: 1 | R17: 3 | S17: [ASK] Report row 13. Trophy; may have leased. | T17: https://hamptonscommercialre.com/properties/retail-storefront-in-the-core-shopping-district-of-east-hampton-village/ | https://hamptonscommercialre.com/properties/prime-east-hampton-village-retail/
A18: 32 Park Place (two units) | B18: 32 Park Pl | C18: East Hampton Village | D18: Boutique retail | E18: 778 | F18: NNN | G18: 120000 | H18: =IF(ISNUMBER(G18),G18/12,"n/a") -> 10000 | I18: =IFERROR(IF(ISNUMBER(G18),G18/E18,"n/a"),"n/a") -> 154.24165 | J18: =IF(SUMPRODUCT(($A$42:$A$42=A18)*$B$42:$B$42)>0,SUMPRODUCT(($A$42:$A$42=A18)*$B$42:$B$42)/E18,IF(AND(LEFT(F18,3)="NNN",ISNUMBER(I18)),"Not stated; master "&TEXT('Executive Summary'!$B$8,"$0.00")&" applied","Unknown")) -> Not stated; master $7.00 applied | K18: =IF(AND(ISNUMBER(I18),LEFT(F18,3)="NNN"),I18+IF(ISNUMBER(J18),J18,'Executive Summary'!$B$8)+SUMPRODUCT(($A$37:$A$39=A18)*$B$37:$B$39)/$C$31/E18,"n/a") -> 161.24165 | L18: Unknown | M18: Annual | N18: Modified 2026-02-24 | O18: [56] | P18: B | Q18: 1 | R18: 3 | S18: [ASK] Report row 14. Two units, 778 SF and 807 SF, at $120,000 each ($154.24 / $148.70/SF); this row is computed on the 778 SF unit. Luxury-adjacent; fronts the village public lot. | T18: https://hamptonscommercialre.com/properties/east-hampton-village-retail-two-boutique-units-available-for-lease/
A19: 9 Railroad Ave | B19: 9 Railroad Ave | C19: East Hampton (expanded village district) | D19: Retail gallery, ex-auto shop | E19: 3000 | F19: NNN | G19: 250000 | H19: =IF(ISNUMBER(G19),G19/12,"n/a") -> 20833.333 | I19: =IFERROR(IF(ISNUMBER(G19),G19/E19,"n/a"),"n/a") -> 83.333333 | J19: =IF(SUMPRODUCT(($A$42:$A$42=A19)*$B$42:$B$42)>0,SUMPRODUCT(($A$42:$A$42=A19)*$B$42:$B$42)/E19,IF(AND(LEFT(F19,3)="NNN",ISNUMBER(I19)),"Not stated; master "&TEXT('Executive Summary'!$B$8,"$0.00")&" applied","Unknown")) -> Not stated; master $7.00 applied | K19: =IF(AND(ISNUMBER(I19),LEFT(F19,3)="NNN"),I19+IF(ISNUMBER(J19),J19,'Executive Summary'!$B$8)+SUMPRODUCT(($A$37:$A$39=A19)*$B$37:$B$39)/$C$31/E19,"n/a") -> 90.333333 | L19: Unknown | M19: Annual | N19: Modified 2026-03-06 | O19: [57] | P19: B | Q19: 2 | R19: 3 | S19: [ASK] Report row 15. Four roll-up doors; 'ample parking'. | T19: https://hamptonscommercialre.com/properties/one-of-a-kind-retail-outlet-with-character-in-east-hampton/
A20: 70 Main St, floor 1 | B20: 70 Main St | C20: Southampton Village | D20: Dry retail, wet-use infrastructure retained | E20: 2365 | F20: NNN | G20: 355000 | H20: =IF(ISNUMBER(G20),G20/12,"n/a") -> 29583.333 | I20: =IFERROR(IF(ISNUMBER(G20),G20/E20,"n/a"),"n/a") -> 150.10571 | J20: =IF(SUMPRODUCT(($A$42:$A$42=A20)*$B$42:$B$42)>0,SUMPRODUCT(($A$42:$A$42=A20)*$B$42:$B$42)/E20,IF(AND(LEFT(F20,3)="NNN",ISNUMBER(I20)),"Not stated; master "&TEXT('Executive Summary'!$B$8,"$0.00")&" applied","Unknown")) -> Not stated; master $7.00 applied | K20: =IF(AND(ISNUMBER(I20),LEFT(F20,3)="NNN"),I20+IF(ISNUMBER(J20),J20,'Executive Summary'!$B$8)+SUMPRODUCT(($A$37:$A$39=A20)*$B$37:$B$39)/$C$31/E20,"n/a") -> 157.10571 | L20: Unknown | M20: Annual | N20: Modified 2026-08-19 | O20: [58] | P20: B | Q20: 2 | R20: 3 | S20: [ASK] Report row 16. SF = 2,365 + 1,300 basement (basement excluded from $/SF). Luxury Main St; trophy. | T20: https://hamptonscommercialre.com/properties/70-main-street-floor-1-southampton-retail-for-lease/
A21: Wainscott 900 SF | B21: Montauk Hwy ('81 Montauk Hwy' per D) | C21: Wainscott | D21: Highway boutique; 'hospitality-related use' possible | E21: 900 | F21: NNN per CityFeet (D); HCRE silent | G21: 168000 | H21: =IF(ISNUMBER(G21),G21/12,"n/a") -> 14000 | I21: =IFERROR(IF(ISNUMBER(G21),G21/E21,"n/a"),"n/a") -> 186.66667 | J21: =IF(SUMPRODUCT(($A$42:$A$42=A21)*$B$42:$B$42)>0,SUMPRODUCT(($A$42:$A$42=A21)*$B$42:$B$42)/E21,IF(AND(LEFT(F21,3)="NNN",ISNUMBER(I21)),"Not stated; master "&TEXT('Executive Summary'!$B$8,"$0.00")&" applied","Unknown")) -> Not stated; master $7.00 applied | K21: =IF(AND(ISNUMBER(I21),LEFT(F21,3)="NNN"),I21+IF(ISNUMBER(J21),J21,'Executive Summary'!$B$8)+SUMPRODUCT(($A$37:$A$39=A21)*$B$37:$B$39)/$C$31/E21,"n/a") -> 193.66667 | L21: Unknown | M21: Annual | N21: Modified 2026-08-25 | O21: [59][60] | P21: B | Q21: 1 | R21: 3 | S21: [ASK] Report row 17. Small-unit premium. | T21: https://hamptonscommercialre.com/properties/a-rare-commercial-opportunity-at-the-crossroads-of-the-hamptons-most-prestigious-corridor/ | https://www.cityfeet.com/cont/listing/81-montauk-hwy-wainscott-ny-11975/cs41480188
A22: 62 Montauk Hwy (ex-Buoy One) | B22: 62 Montauk Hwy | C22: Westhampton | D22: Restaurant, 62 parking | E22: 4400 | F22: NNN | G22: 132000 | H22: =IF(ISNUMBER(G22),G22/12,"n/a") -> 11000 | I22: =IFERROR(IF(ISNUMBER(G22),G22/E22,"n/a"),"n/a") -> 30 | J22: =IF(SUMPRODUCT(($A$42:$A$42=A22)*$B$42:$B$42)>0,SUMPRODUCT(($A$42:$A$42=A22)*$B$42:$B$42)/E22,IF(AND(LEFT(F22,3)="NNN",ISNUMBER(I22)),"Not stated; master "&TEXT('Executive Summary'!$B$8,"$0.00")&" applied","Unknown")) -> Not stated; master $7.00 applied | K22: =IF(AND(ISNUMBER(I22),LEFT(F22,3)="NNN"),I22+IF(ISNUMBER(J22),J22,'Executive Summary'!$B$8)+SUMPRODUCT(($A$37:$A$39=A22)*$B$37:$B$39)/$C$31/E22,"n/a") -> 44.954545 | L22: 'Long-term' | M22: Annual | N22: Undated | O22: [61] | P22: D | Q22: 2 | R22: 3 | S22: [ASK] Report row 18. $132,000 is year-1 rent. Plus $350,000 key money (ASK); size and parking conflict with another source. Report's gross-equiv. ($37.00) excludes key money. | T22: https://www.bizquest.com/real-estate-for-lease/premier-westhampton-restaurant-opportunity/BW2453378
A23: 2 Main St | B23: 2 Main St | C23: Sag Harbor | D23: Small boutique | E23: 744 | F23: NNN | G23: 120000 | H23: =IF(ISNUMBER(G23),G23/12,"n/a") -> 10000 | I23: =IFERROR(IF(ISNUMBER(G23),G23/E23,"n/a"),"n/a") -> 161.29032 | J23: =IF(SUMPRODUCT(($A$42:$A$42=A23)*$B$42:$B$42)>0,SUMPRODUCT(($A$42:$A$42=A23)*$B$42:$B$42)/E23,IF(AND(LEFT(F23,3)="NNN",ISNUMBER(I23)),"Not stated; master "&TEXT('Executive Summary'!$B$8,"$0.00")&" applied","Unknown")) -> Not stated; master $7.00 applied | K23: =IF(AND(ISNUMBER(I23),LEFT(F23,3)="NNN"),I23+IF(ISNUMBER(J23),J23,'Executive Summary'!$B$8)+SUMPRODUCT(($A$37:$A$39=A23)*$B$37:$B$39)/$C$31/E23,"n/a") -> 168.29032 | L23: Negotiable | M23: Annual | N23: Modified 2026-09-13 | O23: [62] | P23: B | Q23: 1 | R23: 3 | S23: [ASK] Report row 19. Supporting; small-unit. | T23: https://hamptonscommercialre.com/properties/high-visibility-boutique-space/
A24: 117 Main St | B24: 117 Main St | C24: Sag Harbor | D24: Small storefront with patio | E24: 400 | F24: NNN | G24: 96000 | H24: =IF(ISNUMBER(G24),G24/12,"n/a") -> 8000 | I24: =IFERROR(IF(ISNUMBER(G24),G24/E24,"n/a"),"n/a") -> 240 | J24: =IF(SUMPRODUCT(($A$42:$A$42=A24)*$B$42:$B$42)>0,SUMPRODUCT(($A$42:$A$42=A24)*$B$42:$B$42)/E24,IF(AND(LEFT(F24,3)="NNN",ISNUMBER(I24)),"Not stated; master "&TEXT('Executive Summary'!$B$8,"$0.00")&" applied","Unknown")) -> Not stated; master $7.00 applied | K24: =IF(AND(ISNUMBER(I24),LEFT(F24,3)="NNN"),I24+IF(ISNUMBER(J24),J24,'Executive Summary'!$B$8)+SUMPRODUCT(($A$37:$A$39=A24)*$B$37:$B$39)/$C$31/E24,"n/a") -> 247 | L24: 1 year (Oct 2026–Oct 2027) | M24: Annual | N24: Modified 2026-07-23 | O24: [63] | P24: B | Q24: 1 | R24: 3 | S24: [ASK] Report row 20. SF approximate (~400). Trophy small-unit; EXCLUDED. | T24: https://hamptonscommercialre.com/properties/sag-harbor-main-street-retail/
A25: 7 Hill St (inline) | B25: 7 Hill St | C25: Southampton Village | D25: Inline retail; 'modified wet uses such as salon or ice cream' | E25: 925 | F25: NNN | G25: 66000 | H25: =IF(ISNUMBER(G25),G25/12,"n/a") -> 5500 | I25: =IFERROR(IF(ISNUMBER(G25),G25/E25,"n/a"),"n/a") -> 71.351351 | J25: =IF(SUMPRODUCT(($A$42:$A$42=A25)*$B$42:$B$42)>0,SUMPRODUCT(($A$42:$A$42=A25)*$B$42:$B$42)/E25,IF(AND(LEFT(F25,3)="NNN",ISNUMBER(I25)),"Not stated; master "&TEXT('Executive Summary'!$B$8,"$0.00")&" applied","Unknown")) -> Not stated; master $7.00 applied | K25: =IF(AND(ISNUMBER(I25),LEFT(F25,3)="NNN"),I25+IF(ISNUMBER(J25),J25,'Executive Summary'!$B$8)+SUMPRODUCT(($A$37:$A$39=A25)*$B$37:$B$39)/$C$31/E25,"n/a") -> 78.351351 | L25: Unknown | M25: Annual | N25: Modified 2026-09-18 | O25: [64][65] | P25: B (conflict) | Q25: 2 | R25: 3 | S25: [ASK] Report row 21. Combined-unit page implies $84,000 ($90.81/SF); report uses the lower $66,000. Closest size match among food-capable Tier 3 units. | T25: https://hamptonscommercialre.com/properties/inline-retail-store-in-southamptons-cultural-hub/ | https://hamptonscommercialre.com/properties/1-windmill-lane-7-hill-st-southampton/
A26: 15 Hill St, Unit B | B26: 15 Hill St | C26: Southampton Village | D26: Grocery, modified cooking | E26: 3100 | F26: NNN | G26: 240000 | H26: =IF(ISNUMBER(G26),G26/12,"n/a") -> 20000 | I26: =IFERROR(IF(ISNUMBER(G26),G26/E26,"n/a"),"n/a") -> 77.419355 | J26: =IF(SUMPRODUCT(($A$42:$A$42=A26)*$B$42:$B$42)>0,SUMPRODUCT(($A$42:$A$42=A26)*$B$42:$B$42)/E26,IF(AND(LEFT(F26,3)="NNN",ISNUMBER(I26)),"Not stated; master "&TEXT('Executive Summary'!$B$8,"$0.00")&" applied","Unknown")) -> Not stated; master $7.00 applied | K26: =IF(AND(ISNUMBER(I26),LEFT(F26,3)="NNN"),I26+IF(ISNUMBER(J26),J26,'Executive Summary'!$B$8)+SUMPRODUCT(($A$37:$A$39=A26)*$B$37:$B$39)/$C$31/E26,"n/a") -> 84.419355 | L26: Unknown | M26: Annual | N26: Modified 2026-09-28 | O26: [66] | P26: B | Q26: 2 | R26: 3 | S26: [ASK] Report row 22. Food-adjacent. | T26: https://hamptonscommercialre.com/properties/southampton-village-grocery-opportunity-at-15-hill-street-unit-b-southampton-ny/
A27: 87 North Rd bar/restaurant | B27: 87 North Rd | C27: Shinnecock Hills / Hampton Bays | D27: Bar/restaurant with kitchen | E27: 1700 | F27: Unstated | G27: 78000 | H27: =IF(ISNUMBER(G27),G27/12,"n/a") -> 6500 | I27: =IFERROR(IF(ISNUMBER(G27),G27/E27,"n/a"),"n/a") -> 45.882353 | J27: =IF(SUMPRODUCT(($A$42:$A$42=A27)*$B$42:$B$42)>0,SUMPRODUCT(($A$42:$A$42=A27)*$B$42:$B$42)/E27,IF(AND(LEFT(F27,3)="NNN",ISNUMBER(I27)),"Not stated; master "&TEXT('Executive Summary'!$B$8,"$0.00")&" applied","Unknown")) -> Unknown | K27: =IF(AND(ISNUMBER(I27),LEFT(F27,3)="NNN"),I27+IF(ISNUMBER(J27),J27,'Executive Summary'!$B$8)+SUMPRODUCT(($A$37:$A$39=A27)*$B$37:$B$39)/$C$31/E27,"n/a") -> n/a | L27: Unknown | M27: Unknown | N27: 2024-05-18 | O27: [67] | P27: B | Q27: 2 | R27: 3 | S27: [ASK] Report row 23. Peripheral Southampton Town location. Lease type unstated, so no effective rent is computed (report: Unknown). | T27: https://behindthehedges.com/bar-restaurant-available-lease-highly-visible/
A30: SUPPLEMENTARY INPUTS (referenced by the formulas above)
A31: Key-money amortization period (years) | C31: 10 | D31: Report convention 7: key money converted straight-line over an assumed 10-year term. Used in Effective Rent/SF and in the Adjustments key-money check.
A32: Seasonal share of annual rent, low (two-thirds) | C32: 0.67 | D32: Broker rule: a 4–6 month season costs 'two-thirds to three-fourths of the annual asking rent' [91]; 74A's 2026 asks confirm (72.9%) [28].
A33: Seasonal share of annual rent, high (three-fourths) | C33: 0.75
A34: Seasonal share, midpoint (used in Adjustments) | C34: =AVERAGE(C32:C33) -> 0.71 | D34: Report divides seasonal rent by 0.71 (midpoint) to reach an annual equivalent.
A36: Property (key money) | B36: Key money ($, ASK) | C36: Source | D36: Key money $/SF/yr | E36: Note
A37: =A5 -> Former Coche Comedor (annual option) | B37: 700000 | C37: [28] | D37: =B37/$C$31/E5 -> 24.734982 | E37: Includes ownership of all equipment [28]
A38: =A15 -> 17 S Edison St restaurant | B38: 250000 | C38: [50] | D38: =B38/$C$31/E15 -> 9.1608648 | E38: Turnkey restaurant
A39: =A22 -> 62 Montauk Hwy (ex-Buoy One) | B39: 350000 | C39: [61] | D39: =B39/$C$31/E22 -> 7.9545455 | E39: D-grade source
A41: Property (stated NNN) | B41: Stated NNN ($/yr) | C41: Source | D41: Stated NNN $/SF | E41: Note
A42: =A12 -> 2095 Montauk Hwy restaurant | B42: 40000 | C42: [42] | D42: =B42/E12 -> 8.9365505 | E42: '$180,000 base plus $40,000 NNN' (Compass, closed 2025-06-08)
A44: Property (seasonal) | B44: Seasonal rent ($) | C44: Season | D44: SF basis (low) | E44: SF basis (high) | F44: $/SF per season (low) | G44: $/SF per season (high) | H44: Annual-equiv. $/SF low (÷0.75) | I44: Annual-equiv. $/SF high (÷0.67)
A45: =A6 -> Same space (seasonal option) | B45: 175000 | C45: May 22–Sep 15, 2026 | D45: 2830 | E45: 2830 | F45: =B45/E45 -> 61.837456 | G45: =B45/D45 -> 61.837456 | H45: =F45/$C$33 -> 82.449941 | I45: =G45/$C$32 -> 92.29471
...

Sheet Executed Transactions
A1: Executed Transactions — executed / closed items only
A2: No executed Amagansett commercial rent is publicly disclosed for 2014–2026.
A3: Same columns as Comparable Properties. Rows for 2095 Montauk Hwy and GreyVen link to the Comparable Properties tab (green). About 45 searches and 30 page fetches (press archives, broker closed-deal pages, Traded.co, court, SEC and County Clerk records) found no other disclosed rent.
A4: Property | B4: Address | C4: City | D4: Property Type | E4: SF | F4: Lease Type | G4: Annual Base Rent | H4: Monthly Base Rent | I4: Rent/SF | J4: NNN/CAM | K4: Effective Rent/SF | L4: Lease Term | M4: Seasonality | N4: Date | O4: Source | P4: Source Quality | Q4: Comparability Score | R4: Tier | S4: Notes | T4: Source URL
A5: 207 Main St lease assignment (Mary's Marvelous → Organic Krush) — SUBJECT | B5: 207 Main St | C5: Amagansett | D5: Café / bakery storefront with kitchen and patio | E5: ='Executive Summary'!$B$6 -> 1100 | F5: Unknown ('long-term lease') | G5: Undisclosed | H5: =IF(ISNUMBER(G5),G5/12,"n/a") -> n/a | I5: =IFERROR(IF(ISNUMBER(G5),G5/E5,"n/a"),"n/a") -> n/a | J5: =IF(AND(LEFT(F5,3)="NNN",ISNUMBER(I5)),"Not stated; master "&TEXT('Executive Summary'!$B$8,"$0.00")&" applied","Unknown") -> Unknown | K5: =IF(AND(ISNUMBER(I5),LEFT(F5,3)="NNN"),I5+'Executive Summary'!$B$8,"n/a") -> n/a | L5: Long-term; remaining term undisclosed | M5: Annual (seasonal winter closures) | N5: Closed 2017-06-12 | O5: [10][13][15] | P5: B (broker-confirmed completed transaction) | Q5: Subject | R5: 1 | S5: [EXECUTED / HISTORICAL — price and rent undisclosed] Assignment of the 'long-term lease' and equipment; key money ASK $625,000 (Dec 2016) [10], later quoted $575,000 [13]; closing price, contract rent, remaining term and lease type never published. Implication: market participants paid a premium to occupy this space; contract rent below market at the time (inference). See key-money capitalization illustration below (ESTIMATE, not used in the market-rent calculation). | T5: https://www.27east.com/real-estate-news/marys-marvelous-in-amagansett-to-close-when-new-tenant-is-found-1404430 | https://behindthehedges.com/marys-marvelous-amagansett-shut-organic-krush-open/ | https://27east.com/east-hampton-press/marys-marvelous-leaves-amagansett-organic-krush-to-move-in-1633346
A6: 177 Main St — 2020 building sale | B6: 177 Main St | C6: Amagansett | D6: Restaurant building (fee sale, Indian Wells Tavern) | E6: 2900 | F6: n/a (sale) | G6: n/a — fee sale $2,825,000 | H6: =IF(ISNUMBER(G6),G6/12,"n/a") -> n/a | I6: =IFERROR(IF(ISNUMBER(G6),G6/E6,"n/a"),"n/a") -> n/a | J6: =IF(AND(LEFT(F6,3)="NNN",ISNUMBER(I6)),"Not stated; master "&TEXT('Executive Summary'!$B$8,"$0.00")&" applied","Unknown") -> Unknown | K6: =IF(AND(ISNUMBER(I6),LEFT(F6,3)="NNN"),I6+'Executive Summary'!$B$8,"n/a") -> n/a | L6: n/a | M6: Annual | N6: 2020 | O6: [81] | P6: C | Q6: Not a rent comp | R6: 1 | S6: [EXECUTED — SALE; NOT A RENT COMP] Building bought for $2.825M. SF ~2,900 per press (2,304 SF ground floor per Town ARB file [7]). | T6: https://www.danspapers.com/2020/02/highway-restaurant-buys-indian-wells-tavern
A7: Hampton Chutney renewal offer | B7: Amagansett Square | C7: Amagansett | D7: Food service (20-year legacy tenant) | E7: Unknown | F7: Unknown | G7: Not disclosed ('almost triple' prior rent) | H7: =IF(ISNUMBER(G7),G7/12,"n/a") -> n/a | I7: =IFERROR(IF(ISNUMBER(G7),G7/E7,"n/a"),"n/a") -> n/a | J7: =IF(AND(LEFT(F7,3)="NNN",ISNUMBER(I7)),"Not stated; master "&TEXT('Executive Summary'!$B$8,"$0.00")&" applied","Unknown") -> Unknown | K7: =IF(AND(ISNUMBER(I7),LEFT(F7,3)="NNN"),I7+'Executive Summary'!$B$8,"n/a") -> n/a | L7: Renewal (offer not accepted) | M7: Unknown | N7: Lease expired Oct 2020; offer spring 2021 | O7: [76][77][24] | P7: C | Q7: Qualitative | R7: 1 | S7: [HISTORICAL — qualitative executed-market event] Landlord's renewal offer at 'almost triple what we're paying now'. Space re-let to Doubles by July 2022; Hampton Chutney moved to 107 Newtown Lane, East Hampton, the former Mary's Marvelous store [77]. | T7: https://easthamptonstar.com/villages/2021527/hampton-chutney-co-squeezed-out-square | https://easthamptonstar.com/business-food/2021812/marvelous-new-home-hampton-chutney-co | https://www.easthamptonstar.com/villages-business/2023216/amagansett-main-street-flux
A8: Warby Parker, 48 Main St | B8: 48 Main St | C8: East Hampton Village | D8: Retail | E8: 1341 | F8: Not stated | G8: 167625 | H8: =IF(ISNUMBER(G8),G8/12,"n/a") -> 13968.75 | I8: =IFERROR(IF(ISNUMBER(G8),G8/E8,"n/a"),"n/a") -> 125 | J8: =IF(AND(LEFT(F8,3)="NNN",ISNUMBER(I8)),"Not stated; master "&TEXT('Executive Summary'!$B$8,"$0.00")&" applied","Unknown") -> Unknown | K8: =IF(AND(ISNUMBER(I8),LEFT(F8,3)="NNN"),I8+'Executive Summary'!$B$8,"n/a") -> n/a | L8: Unknown | M8: Annual | N8: Signed 2022-01-01 | O8: [55] | P8: D | Q8: Not scored | R8: 3 | S8: [EXECUTED (D) — may be an ask] Traded.co labels $125/SF ($167,625/yr) 'asking rent'. Trophy ceiling only; lease type not stated, so no effective rent. | T8: https://traded.co/deals/new-york/retail/lease/48-main-street/
A9: David Lewis Gallery, 53 The Circle | B9: 53 The Circle | C9: East Hampton Village | D9: Gallery | E9: 1645 | F9: Not stated | G9: 120085 | H9: =IF(ISNUMBER(G9),G9/12,"n/a") -> 10007.083 | I9: =IFERROR(IF(ISNUMBER(G9),G9/E9,"n/a"),"n/a") -> 73 | J9: =IF(AND(LEFT(F9,3)="NNN",ISNUMBER(I9)),"Not stated; master "&TEXT('Executive Summary'!$B$8,"$0.00")&" applied","Unknown") -> Unknown | K9: =IF(AND(ISNUMBER(I9),LEFT(F9,3)="NNN"),I9+'Executive Summary'!$B$8,"n/a") -> n/a | L9: Unknown | M9: Annual | N9: 2022-01-01 | O9: [54] | P9: D | Q9: Not scored | R9: 3 | S9: [EXECUTED (D) — labelled 'asking'] Village secondary data point ($73/SF). | T9: https://traded.co/deals/new-york/retail/lease/53-the-circle/
A10: 177 Main St — 2023 sale and Rowdy Hall lease | B10: 177 Main St | C10: Amagansett | D10: Restaurant building; leased to Rowdy Hall (opened Nov 2023) | E10: 2900 | F10: Unknown | G10: Lease rent not disclosed; sale $4,450,000 | H10: =IF(ISNUMBER(G10),G10/12,"n/a") -> n/a | I10: =IFERROR(IF(ISNUMBER(G10),G10/E10,"n/a"),"n/a") -> n/a | J10: =IF(AND(LEFT(F10,3)="NNN",ISNUMBER(I10)),"Not stated; master "&TEXT('Executive Summary'!$B$8,"$0.00")&" applied","Unknown") -> Unknown | K10: =IF(AND(ISNUMBER(I10),LEFT(F10,3)="NNN"),I10+'Executive Summary'!$B$8,"n/a") -> n/a | L10: Unknown | M10: Annual | N10: Sale 2023-01-17; lease 2023 | O10: [80][82][83][7] | P10: B/C | Q10: Not a rent comp | R10: 1 | S10: [EXECUTED — SALE + LEASE; rent undisclosed] Listed $4.995M (Oct 2022), sold $4.45M to ROP Amagansett LLC to lease out; ~58% above the 2020 price. See implied-yield illustration below — NOT A RENT COMP, carries no weight. | T10: https://behindthehedges.com/final-figure-amagansett-restaurant-sells-4-5m | https://www.danspapers.com/2022/10/amagansett-main-street-tavern-restaurant-building-for-sale | https://27east.com/east-hampton-press/rowdy-hall-to-move-from-east-hampton-village-to-amagansett-after-summer-2159344 | https://www.ehamptonny.gov/AgendaCenter/ViewFile/Item/2157?fileID=5624
A11: ='Comparable Properties'!A16 -> 53 The Circle (GreyVen) | B11: ='Comparable Properties'!B16 -> 53 The Circle | C11: ='Comparable Properties'!C16 -> East Hampton Village | D11: ='Comparable Properties'!D16 -> Luxury retail | E11: ='Comparable Properties'!E16 -> 1635 | F11: ='Comparable Properties'!F16 -> NNN | G11: ='Comparable Properties'!G16 -> 237075 | H11: ='Comparable Properties'!H16 -> 19756.25 | ... R11: ='Comparable Properties'!R16 -> 3 | S11: [EXECUTED per Traded.co, closed 2024-05-09; grade D] $145/SF NNN; corroborated by 6% cap on a $3,959,000 sale ask. Trophy-corridor ceiling; not a restaurant comparable. | T11: ='Comparable Properties'!T16 -> https://traded.co/deals/new-york/retail/lease/53-the-circle-1/
A12: ='Comparable Properties'!A12 -> 2095 Montauk Hwy restaurant | B12: ='Comparable Properties'!B12 -> 2095 Montauk Hwy | C12: ='Comparable Properties'!C12 -> Amagansett 11930 (Napeague, ~6 mi east of core) | D12: ='Comparable Properties'!D12 -> Restaurant, white box, 123 seats, double hood, 3BR apartment | E12: ='Comparable Properties'!E12 -> 4476 | F12: ='Comparable Properties'!F12 -> NNN | G12: ='Comparable Properties'!G12 -> 180000 | H12: ='Comparable Properties'!H12 -> 15000 | ... R12: ='Comparable Properties'!R12 -> 2 | S12: [CLOSED, broker-reported; Compass flags price 'Unverified'] $180,000 base + $40,000 NNN ($40.21 + $8.94/SF). The only closed Amagansett-ZIP food-service rent; low anchor. | T12: ='Comparable Properties'!T12 -> https://www.compass.com/homedetails/2095-Montauk-Hwy-Amagansett-NY-11930/1826297907410452777_lid/ | https://www.compass.com/agents/the-hamptons-commercial-real-estate-team/ | https://behindthehedges.com/fall-2024-food-market-commercial-real-estate
A13: Sea Dragon Books, 136 Main St | B13: 136 Main St | C13: Amagansett | D13: Bookstore (retail) | E13: Unknown | F13: Unknown | G13: Not disclosed | H13: =IF(ISNUMBER(G13),G13/12,"n/a") -> n/a | I13: =IFERROR(IF(ISNUMBER(G13),G13/E13,"n/a"),"n/a") -> n/a | J13: =IF(AND(LEFT(F13,3)="NNN",ISNUMBER(I13)),"Not stated; master "&TEXT('Executive Summary'!$B$8,"$0.00")&" applied","Unknown") -> Unknown | K13: =IF(AND(ISNUMBER(I13),LEFT(F13,3)="NNN"),I13+'Executive Summary'!$B$8,"n/a") -> n/a | L13: Two-year lease | M13: Unknown | N13: 2026 | O13: [86] | P13: C | Q13: Not scored | R13: 2 | S13: [EXECUTED — rent undisclosed] Confirms leasing activity on the Main Street frontage. | T13: https://easthamptonstar.com/villages-business/202672/amagansetts-west-end-sees-business-boom
A15: ILLUSTRATION (ESTIMATE): 2016–17 key money capitalized as an annual rent differential — loose upper bound, NOT used in the market-rent calculation
A16: Discount rate (assumed) | B16: 0.1 | C16: Assumed 10% rate from the executed-transactions research; remaining terms are assumptions.
A17: Key money (ASK) | B17: Amount | C17: Source | D17: 10-yr: annual | E17: 10-yr: monthly | F17: 15-yr: annual | G17: 15-yr: monthly | H17: 20-yr: annual | I17: 20-yr: monthly
A18: Remaining term (years) | D18: 10 | F18: 15 | H18: 20
A19: Later quote | B19: 575000 | C19: [13] | D19: =PMT($B$16,D$18,-$B19) -> 93578.602 | E19: =D19/12 -> 7798.2168 | F19: =PMT($B$16,F$18,-$B19) -> 75597.422 | G19: =F19/12 -> 6299.7851 | H19: =PMT($B$16,H$18,-$B19) -> 67539.284 | I19: =H19/12 -> 5628.2737
A20: Original ask | B20: 625000 | C20: [10] | D20: =PMT($B$16,D$18,-$B20) -> 101715.87 | E20: =D20/12 -> 8476.3227 | F20: =PMT($B$16,F$18,-$B20) -> 82171.111 | G20: =F20/12 -> 6847.5925 | H20: =PMT($B$16,H$18,-$B20) -> 73412.265 | I20: =H20/12 -> 6117.6888
A21: Report check: $575,000 → $93,579 / $75,597 / $67,539 per year; $625,000 → $101,716 / $82,171 / $73,412. Part of the payment bought used equipment, goodwill and the scarce wet-use status, so the figures are directional only: in 2016–17 informed buyers valued this leasehold above its contract rent.
A23: 177 MAIN STREET IMPLIED-YIELD ILLUSTRATION — ESTIMATE ONLY, NOT A RENT COMP (carries no weight in the calculation)
A24: 2023 sale price ($) | B24: 4450000 | C24: [80]
A25: 2020 sale price ($) | B25: 2825000 | C25: [81]
A26: Investor yield, low (assumed, unsourced) | B26: 0.055 | C26: Assumption
A27: Investor yield, high (assumed, unsourced) | B27: 0.065 | C27: Assumption
A28: Building SF per press coverage | B28: 2900 | C28: Press coverage
A29: Ground-floor SF per Town ARB file | B29: 2304 | C29: [7] (also 650 SF lower level, 94 seats)
A31: Output (ESTIMATE) | B31: Low yield | C31: High yield
A32: Implied net income ($/yr) | B32: =$B$24*$B$26 -> 244750 | C32: =$B$24*$B$27 -> 289250
A33: Implied $/SF on ~2,900 SF | B33: =B32/$B$28 -> 84.396552 | C33: =C32/$B$28 -> 99.741379
A34: Implied $/SF on 2,304 SF ground floor | B34: =B32/$B$29 -> 106.2283 | C34: =C32/$B$29 -> 125.54253
A35: Price change 2020 → 2023 | B35: =$B$24/$B$25-1 -> 0.57522124
A36: Report check: $244,750–$289,250/yr; $84–$100/SF on ~2,900 SF; about $106–$126/SF on 2,304 SF; price up about 58%. Inferred from a sale price, not a lease; the buyer may have priced in land value or upside.
A38: NOTES & SOURCES
A39: Asking vs executed: most figures in this workbook are ASKING rents on listings, not executed leases. No executed Amagansett commercial rent is publicly disclosed for 2014–2026. The only closed Amagansett-ZIP food-service lease (2095 Montauk Hwy, closed 2025-06-08) is broker-reported and Compass flags its price 'Unverified' [42]. Asks are converted to an achieved basis with a moderate 5–10% discount (asks on market >180 days without a cut −10%; other asks −5%; closed 0%). Trophy village rows ($145–$240/SF) are excluded from the conclusion except as an outer ceiling.
A40: NNN assumption ($7.00/SF, range $5.00–$8.75; master input on Executive Summary): real estate taxes from broker-published tax bills run $1.38–$3.22/SF on small village commercial buildings [68][69][70][71]; the subject's own taxes are about $2.96/SF [3]; taxes alone at 74A are $4.92/SF [31]; the one stated all-in Amagansett NNN figure is $8.94/SF at 2095 Montauk Highway [42]; taxes at 136 Main / 11 Indian Wells run about $1.31–$2.02/SF [36]; and a generic national benchmark puts retail NNN at $4–$8/SF [72]. Insurance and maintenance components (about $1.00–$2.50 and $1.00–$3.00/SF respectively) are unsourced assumptions and should be replaced with the subject's actual figures.
A41: Labels: ASK = asking rent on a listing; EXECUTED/CLOSED = signed, assigned or broker-reported closed lease; HISTORICAL = dated past listing or event; BROKER OPINION = broker's quoted range; ESTIMATE = figure inferred or calculated in the report. Grades: A = government record or recorded transaction; B = broker listing with detailed terms or established real estate publication; C = historical listing, local newspaper or business website; D = aggregator, unverified database or search snippet.
A42: Source: '207 Main Street, Amagansett — Commercial Market Rent Assessment', effective 2026-10-07 (research/reports/207 Main Street Amagansett market rent.md). Bracketed numbers refer to the Sources tab, which lists every URL (all accessed 2026-10-07).

Sheet Historical Listings
A1: Historical Listings — dated time series, 1997–2026
A2: From the report's Historical Market Evidence section (plus its Montauk notes and the subject's own 2016–2017 listing history). Ordered by date. No archived listing captures exist (Wayback CDX blocked; LoopNet/Crexi 403).
A3: Label for each event is shown in brackets at the start of Event / Listing. Green cells link to the Comparable Properties or Executed Transactions tabs.
A4: Property | B4: Address | C4: Hamlet | D4: Date | E4: Event / Listing | F4: Asking Rent | G4: $/SF | H4: Seasonal / Annual | I4: Outcome | J4: Source | K4: Grade | L4: Source URL
A5: East Hampton Village retail (trend line) | B5: Village core (Main St / Newtown Ln) | C5: East Hampton Village | D5: 1997-05 | E5: [BROKER OPINION] Village retail $45–$70/SF; spaces under 1,000 SF 'proportionately more' | F5: n/a (broker range) | G5: $45–$70 | H5: Annual | I5: Market commentary | J5: [87] | K5: C | L5: https://www.easthamptonstar.com/archive/village-going-going
A6: East Hampton Village prime (trend line) | B6: Prime village blocks | C6: East Hampton Village | D6: 2007–08 | E6: [BROKER OPINION] Prime village retail 'up to $250 a foot' | F6: n/a (broker range) | G6: up to $250 | H6: Annual | I6: Pre-crisis peak | J6: [88] | K6: B | L6: https://therealdeal.com/magazine/new-york-june-2009/retail-cools-in-hamptons
A7: East Hampton Village; Montauk (trend line) | B7: Village core; Montauk | C7: East Hampton Village / Montauk | D7: 2009-06 | E7: [BROKER OPINION] $175–$200/SF asks; achieved 20–25% below unchanged asks; Montauk landlords 'giving 20 to 30 percent off' | F7: n/a (broker range) | G7: $175–$200 (ask) | H7: Annual | I7: Achieved 20–25% below asks (EH); 20–30% off (Montauk) | J7: [88] | K7: B | L7: https://therealdeal.com/magazine/new-york-june-2009/retail-cools-in-hamptons
A8: East Hampton / Southampton / Bridgehampton–Sag Harbor (trend line) | B8: Village cores | C8: East Hampton; Southampton; Bridgehampton; Sag Harbor | D8: 2011 | E8: [BROKER OPINION] Multiyear leases $110–$140 (EH), $70–$75 (Southampton), about $50 (Bridgehampton, Sag Harbor) | F8: n/a (broker range) | G8: $110–$140 (EH); $70–$75 (SH); ~$50 (BH/SgH) | H8: Annual | I8: Post-crisis trough; 'prime shopping season is just three months' | J8: [89] | K8: B | L8: https://www.corcoran.com/nyc/press-mention/display/12619
A9: Outdoors store | B9: Main St | C9: Amagansett | D9: 2012-04 | E9: [HISTORICAL] 15-year lease not renewed | F9: Undisclosed | G9: n/a | H9: Annual | I9: Space later split between two tenants | J9: [125][74] | K9: C | L9: https://www.easthamptonstar.com/archive/outdoors-heading-out | https://www.easthamptonstar.com/archive/square-dance-amagansett
A10: Gone Local | B10: Main St | C10: Amagansett | D10: 2013-05 | E10: [HISTORICAL] Month-to-month tenant evicted; owner could afford 'as much as $5,000 per month' for a new space | F10: Tenant budget ≤ $5,000/mo (not a rent) | G10: n/a | H10: Month-to-month | I10: Tenant relocated | J10: [73] | K10: C | L10: https://patch.com/new-york/easthampton/gone-local-goes-looking-for-a-new-space
A11: Amagansett Square | B11: Amagansett Square, Main St | C11: Amagansett | D11: 2015–16 | E11: [HISTORICAL] Four vacancies in late 2015 | F11: n/a | G11: n/a | H11: Annual | I11: Square 'filled to capacity' by May 2016 | J11: [74][75] | K11: C | L11: https://www.easthamptonstar.com/archive/square-dance-amagansett | https://www.easthamptonstar.com/archive/lifestyle-shops-fill-gansett-square-capacity
A12: East Hampton Village / Southampton (trend line) | B12: Village cores | C12: East Hampton Village; Southampton | D12: 2016-02 | E12: [BROKER OPINION] Average $125/SF (EH); $90/SF (Southampton) | F12: n/a (broker average) | G12: $125 (EH); $90 (SH) | H12: Annual | I12: Market commentary | J12: [90] | K12: C | L12: https://www.27east.com/real-estate-news/pulse-points-1407695
A13: 2510 Montauk Hwy corner building | B13: 2510 Montauk Hwy | C13: Bridgehampton | D13: 2016-12 | E13: [ASK] Main floor $70/SF plus taxes and CAM | F13: n/a | G13: 70 | H13: Annual | I13: Outcome unknown | J13: [99] | K13: C | L13: https://www.easthamptonstar.com/archive/corner-building-1075-million
A14: 207 Main St — SUBJECT (Mary's Marvelous leasehold) | B14: 207 Main St | C14: Amagansett | D14: 2016-12-08 | E14: [HISTORICAL ASK] Douglas Elliman markets 'key money' for the business, long-term lease and equipment; contract rent not published | F14: Key money ASK $625,000 (rent undisclosed) | G14: n/a | H14: Annual | I14: 'Several serious inquiries' within a day | J14: [9][10][12] | K14: B | L14: https://patch.com/new-york/riverhead/marys-marvelous-amagansett-close-new-tenant-sought | https://www.27east.com/real-estate-news/marys-marvelous-in-amagansett-to-close-when-new-tenant-is-found-1404430 | https://behindthehedges.com/marys-marvelous-in-amagansett-closing-and-available-to-lease/
A15: 716 Montauk Hwy retail plaza | B15: 716 Montauk Hwy | C15: Montauk | D15: 2016 → 2017-03 | E15: [HISTORICAL — SALE ASK] Sale price cut from $8.9M (2016) to $6.7M (March 2017) | F15: n/a (sale ask) | G15: n/a | H15: n/a | I15: Montauk cyclical discounting | J15: [97] | K15: B | L15: https://behindthehedges.com/montauk-retail-plaza-cheaper
A16: 207 Main St — SUBJECT (lease assignment) | B16: 207 Main St | C16: Amagansett | D16: 2017-06-12 | E16: [EXECUTED] Assignment to Organic Krush closed Monday, June 12, 2017; price not disclosed | F16: Undisclosed | G16: n/a | H16: Annual | I16: Organic Krush opened June 2017 | J16: [15] | K16: B | L16: https://27east.com/east-hampton-press/marys-marvelous-leaves-amagansett-organic-krush-to-move-in-1633346
A17: 207 Main St — SUBJECT (reported price) | B17: 207 Main St | C17: Amagansett | D17: 2017-06-15 | E17: [HISTORICAL] Behind the Hedges: 'the lease, listed for $575K, has sold' (27east cites only $625,000) | F17: Key money quoted $575,000 (rent undisclosed) | G17: n/a | H17: Annual | I17: Leasehold assigned ($625K → $575K key money) | J17: [13][14] | K17: B/C | L17: https://behindthehedges.com/marys-marvelous-amagansett-shut-organic-krush-open/ | https://www.danspapers.com/2017/06/behind-the-hedges-organic-krush-in-amagansett
A18: Southampton (trend line) | B18: Main St; Jobs Ln | C18: Southampton Village | D18: 2017-07 | E18: [BROKER OPINION] Main St $140–$150; Jobs Lane $100–$110; pop-ups (4–6 months) at 'two-thirds to three-fourths of the annual asking rent' | F18: n/a (broker range) | G18: $140–$150 (Main); $100–$110 (Jobs) | H18: Annual; pop-ups seasonal | I18: Basis of the 0.67–0.75 seasonal factor | J18: [91] | K18: B | L18: https://therealdeal.com/magazine/new-york-july-2017/fashion-and-furnishings-lead-a-retail-revival-in-southampton/
A19: 74A Montauk Hwy (Coche Comedor) | B19: 74A Montauk Hwy | C19: Amagansett | D19: 2019-05 | E19: [HISTORICAL] Honest Man opened Coche Comedor; 'The company already owned the space' | F19: n/a | G19: n/a | H19: Annual | I19: Owner-occupied | J19: [79] | K19: B | L19: https://therealdeal.com/tristate/issues_articles/the-hamptons-new-hotspots
A20: Southampton / Amagansett (trend line) | B20: Village cores | C20: Southampton; Amagansett | D20: 2019-06 | E20: [BROKER OPINION] Southampton asks fell from ~$110 to $85 (Main) and $50 (Jobs Lane); 'Sag Harbor, Amagansett and Bridgehampton saw little turnover' | F20: Entry-level pop-ups $75,000–$100,000/season | G20: $85 (Main); $50 (Jobs) | H20: Annual; pop-ups seasonal | I20: Amagansett: little turnover | J20: [92] | K20: B | L20: https://therealdeal.com/new-york/tristate/2019/06/03/revolving-retail-in-the-hamptons/
A21: 177 Main St (Indian Wells Tavern) | B21: 177 Main St | C21: Amagansett | D21: 2020 | E21: [EXECUTED — SALE] Building bought for $2.825M | F21: n/a (sale) | G21: n/a | H21: n/a | I21: Re-sold 2023 for $4.45M | J21: [81] | K21: C | L21: https://www.danspapers.com/2020/02/highway-restaurant-buys-indian-wells-tavern
A22: Martell's / Montauk Fuels | B22: Montauk | C22: Montauk | D22: 2016 → 2021 | E22: [HISTORICAL — SALE ASK] Sale-ask series from $10.5M (2016) to $5.475M (2021) | F22: n/a (sale ask) | G22: n/a | H22: n/a | I22: Montauk cyclical discounting | J22: [127] | K22: B | L22: https://behindthehedges.com/two-commercial-properties-in-montauk-back-on-the-market/
A23: 249 Main St, Building B pop-up | B23: 249 Main St | C23: Amagansett | D23: 2021 | E23: [HISTORICAL ASK] Seasonal pop-up '50K' for May 1–Sept 2021 (basis ambiguous) | F23: ='Comparable Properties'!B46 -> 50000 | G23: =TEXT('Comparable Properties'!F46,"$0")&"–"&TEXT('Comparable Properties'!G46,"$0")&" per season" -> $25–$50 per season | H23: Seasonal | I23: Outcome unknown | J23: [47] | K23: C | L23: https://www.corcoran.com/listing/for-rent/249-main-street-amagansett-ny-11930/5981523/regionId/3
A24: Hampton Chutney (Amagansett Square) | B24: Amagansett Square | C24: Amagansett | D24: 2021-05 | E24: [HISTORICAL — OFFER] Renewal offered at 'almost triple' the prior rent | F24: Not disclosed (~3x prior) | G24: n/a | H24: Annual | I24: Not accepted; Doubles opened in the space July 2022 | J24: [76][77][24] | K24: C | L24: https://easthamptonstar.com/villages/2021527/hampton-chutney-co-squeezed-out-square | https://easthamptonstar.com/business-food/2021812/marvelous-new-home-hampton-chutney-co | https://www.easthamptonstar.com/villages-business/2023216/amagansett-main-street-flux
A25: East Hampton Village Main / Newtown (trend line) | B25: Main St; Newtown Ln | C25: East Hampton Village | D25: 2021-09 | E25: [BROKER OPINION] Average $125–$150/SF | F25: n/a (broker average) | G25: $125–$150 | H25: Annual | I25: Post-COVID recovery | J25: [93] | K25: C | L25: https://www.easthamptonstar.com/villages/202192/general-store-east-hampton-its-challenge
A26: 136 Main St; 11 Indian Wells Hwy | B26: 136 Main St; 11 Indian Wells Hwy | C26: Amagansett | D26: 2021-11 / 2022-12 | E26: [EXECUTED — SALES] Sold for $5.6M and $5.2M to the same group | F26: n/a (sales) | G26: n/a | H26: n/a | I26: Assemblage offered for sale at $19M in 2026 | J26: [85][84] | K26: C/B | L26: https://www.easthamptonstar.com/business/2022317/recorded-deeds-031722 | https://behindthehedges.com/amagansett-applied-arts-building-sells-5-2-m
A27: East Hampton Village retail leases (trend line) | B27: 53 The Circle; 48 Main St | C27: East Hampton Village | D27: 2022–24 | E27: [EXECUTED (D)] Retail leases at $73, $125 and $145/SF (David Lewis 2022, Warby Parker 2022, GreyVen 2024) | F27: See Executed Transactions | G27: =TEXT('Executed Transactions'!I9,"$0")&" / "&TEXT('Executed Transactions'!I8,"$0")&" / "&TEXT('Executed Transactions'!I11,"$0") -> $73 / $125 / $145 | H27: Annual | I27: Trophy ceiling only | J27: [53][54][55] | K27: D | L27: https://traded.co/deals/new-york/retail/lease/53-the-circle-1/ | https://traded.co/deals/new-york/retail/lease/53-the-circle/ | https://traded.co/deals/new-york/retail/lease/48-main-street/
A28: East End retail (trend line) | B28: East End | C28: East End | D28: 2022-11 | E28: [BROKER OPINION — market data] About $46/SF; +9.8% over 12 months; +62.2% vs a decade earlier (likely CoStar-sourced) | F28: n/a (market average) | G28: 46 | H28: Annual | I28: Basis of the +10% market-timing adjustment | J28: [94] | K28: B | L28: https://behindthehedges.com/southampton-restaurant-sale-first-time-20/
